INFO:     Will watch for changes in these directories: ['D:\\h2sql\\app']
INFO:     Uvicorn running on http://0.0.0.0:11901 (Press CTRL+C to quit)
INFO:     Started reloader process [26260] using WatchFiles
INFO:     Started server process [20148]
INFO:     Waiting for application startup.
INFO:     Application startup complete.
INFO:     127.0.0.1:57169 - "GET /health HTTP/1.1" 200 OK
INFO:     127.0.0.1:57172 - "GET /health HTTP/1.1" 200 OK
INFO:     127.0.0.1:57245 - "GET /health HTTP/1.1" 200 OK
2025-10-25 13:56:35,868 INFO sqlalchemy.engine.Engine select pg_catalog.version()
2025-10-25 13:56:35,868 INFO sqlalchemy.engine.Engine [raw sql] ()
2025-10-25 13:56:35,871 INFO sqlalchemy.engine.Engine select current_schema()
2025-10-25 13:56:35,873 INFO sqlalchemy.engine.Engine [raw sql] ()
2025-10-25 13:56:35,876 INFO sqlalchemy.engine.Engine show standard_conforming_strings
2025-10-25 13:56:35,876 INFO sqlalchemy.engine.Engine [raw sql] ()
2025-10-25 13:56:35,878 INFO sqlalchemy.engine.Engine BEGIN (implicit)
2025-10-25 13:56:35,879 INFO sqlalchemy.engine.Engine SELECT projects.id, projects.name, projects.train_id, projects.connection, projects.db_metadata, projects.create_date, projects.update_date 
FROM projects
2025-10-25 13:56:35,879 INFO sqlalchemy.engine.Engine [generated in 0.00008s] ()
2025-10-25 13:56:35,883 INFO sqlalchemy.engine.Engine ROLLBACK
INFO:     127.0.0.1:57264 - "GET /h2s/db/projects HTTP/1.1" 500 Internal Server Error
ERROR:    Exception in ASGI application
Traceback (most recent call last):
  File "C:\Users\sjalagam\AppData\Local\Programs\Python\Python313\Lib\site-packages\uvicorn\protocols\http\httptools_impl.py", line 409, in run_asgi
    result = await app(  # type: ignore[func-returns-value]
             ^^^^^^^^^^^^^^^^^^^^^^^^^^^^^^^^^^^^^^^^^^^^^^
        self.scope, self.receive, self.send
        ^^^^^^^^^^^^^^^^^^^^^^^^^^^^^^^^^^^
    )
    ^
  File "C:\Users\sjalagam\AppData\Local\Programs\Python\Python313\Lib\site-packages\uvicorn\middleware\proxy_headers.py", line 60, in __call__
    return await self.app(scope, receive, send)
           ^^^^^^^^^^^^^^^^^^^^^^^^^^^^^^^^^^^^
  File "C:\Users\sjalagam\AppData\Local\Programs\Python\Python313\Lib\site-packages\fastapi\applications.py", line 1054, in __call__
    await super().__call__(scope, receive, send)
  File "C:\Users\sjalagam\AppData\Local\Programs\Python\Python313\Lib\site-packages\starlette\applications.py", line 112, in __call__
    await self.middleware_stack(scope, receive, send)
  File "C:\Users\sjalagam\AppData\Local\Programs\Python\Python313\Lib\site-packages\starlette\middleware\errors.py", line 187, in __call__
    raise exc
  File "C:\Users\sjalagam\AppData\Local\Programs\Python\Python313\Lib\site-packages\starlette\middleware\errors.py", line 165, in __call__
    await self.app(scope, receive, _send)
  File "C:\Users\sjalagam\AppData\Local\Programs\Python\Python313\Lib\site-packages\starlette\middleware\cors.py", line 85, in __call__
    await self.app(scope, receive, send)
  File "C:\Users\sjalagam\AppData\Local\Programs\Python\Python313\Lib\site-packages\starlette\middleware\exceptions.py", line 62, in __call__
    await wrap_app_handling_exceptions(self.app, conn)(scope, receive, send)
  File "C:\Users\sjalagam\AppData\Local\Programs\Python\Python313\Lib\site-packages\starlette\_exception_handler.py", line 53, in wrapped_app
    raise exc
  File "C:\Users\sjalagam\AppData\Local\Programs\Python\Python313\Lib\site-packages\starlette\_exception_handler.py", line 42, in wrapped_app
    await app(scope, receive, sender)
  File "C:\Users\sjalagam\AppData\Local\Programs\Python\Python313\Lib\site-packages\starlette\routing.py", line 714, in __call__
    await self.middleware_stack(scope, receive, send)
  File "C:\Users\sjalagam\AppData\Local\Programs\Python\Python313\Lib\site-packages\starlette\routing.py", line 734, in app
    await route.handle(scope, receive, send)
  File "C:\Users\sjalagam\AppData\Local\Programs\Python\Python313\Lib\site-packages\starlette\routing.py", line 288, in handle
    await self.app(scope, receive, send)
  File "C:\Users\sjalagam\AppData\Local\Programs\Python\Python313\Lib\site-packages\starlette\routing.py", line 76, in app
    await wrap_app_handling_exceptions(app, request)(scope, receive, send)
  File "C:\Users\sjalagam\AppData\Local\Programs\Python\Python313\Lib\site-packages\starlette\_exception_handler.py", line 53, in wrapped_app
    raise exc
  File "C:\Users\sjalagam\AppData\Local\Programs\Python\Python313\Lib\site-packages\starlette\_exception_handler.py", line 42, in wrapped_app
    await app(scope, receive, sender)
  File "C:\Users\sjalagam\AppData\Local\Programs\Python\Python313\Lib\site-packages\starlette\routing.py", line 73, in app
    response = await f(request)
               ^^^^^^^^^^^^^^^^
  File "C:\Users\sjalagam\AppData\Local\Programs\Python\Python313\Lib\site-packages\fastapi\routing.py", line 327, in app
    content = await serialize_response(
              ^^^^^^^^^^^^^^^^^^^^^^^^^
    ...<9 lines>...
    )
    ^
  File "C:\Users\sjalagam\AppData\Local\Programs\Python\Python313\Lib\site-packages\fastapi\routing.py", line 176, in serialize_response
    raise ResponseValidationError(
        errors=_normalize_errors(errors), body=response_content
    )
fastapi.exceptions.ResponseValidationError: 1 validation errors:
  {'type': 'list_type', 'loc': ('response',), 'msg': 'Input should be a valid list', 'input': {'projects': [{'id': 18, 'name': 'dev', 'train_id': None, 'connection': <projects.models.ConnectionProfile object at 0x000001B2339581A0>, 'db_metadata': [<projects.models.TableSchema object at 0x000001B2339582F0>]}, {'id': 22, 'name': 'test_project', 'train_id': 'test_train_001', 'connection': <projects.models.ConnectionProfile object at 0x000001B2338CF750>, 'db_metadata': []}]}}

2025-10-25 13:56:41,332 INFO sqlalchemy.engine.Engine BEGIN (implicit)
2025-10-25 13:56:41,332 INFO sqlalchemy.engine.Engine SELECT projects.id, projects.name, projects.train_id, projects.connection, projects.db_metadata, projects.create_date, projects.update_date 
FROM projects
2025-10-25 13:56:41,333 INFO sqlalchemy.engine.Engine [cached since 5.453s ago] ()
2025-10-25 13:56:41,336 INFO sqlalchemy.engine.Engine ROLLBACK
INFO:     127.0.0.1:57280 - "GET /h2s/db/projects HTTP/1.1" 500 Internal Server Error
ERROR:    Exception in ASGI application
Traceback (most recent call last):
  File "C:\Users\sjalagam\AppData\Local\Programs\Python\Python313\Lib\site-packages\uvicorn\protocols\http\httptools_impl.py", line 409, in run_asgi
    result = await app(  # type: ignore[func-returns-value]
             ^^^^^^^^^^^^^^^^^^^^^^^^^^^^^^^^^^^^^^^^^^^^^^
        self.scope, self.receive, self.send
        ^^^^^^^^^^^^^^^^^^^^^^^^^^^^^^^^^^^
    )
    ^
  File "C:\Users\sjalagam\AppData\Local\Programs\Python\Python313\Lib\site-packages\uvicorn\middleware\proxy_headers.py", line 60, in __call__
    return await self.app(scope, receive, send)
           ^^^^^^^^^^^^^^^^^^^^^^^^^^^^^^^^^^^^
  File "C:\Users\sjalagam\AppData\Local\Programs\Python\Python313\Lib\site-packages\fastapi\applications.py", line 1054, in __call__
    await super().__call__(scope, receive, send)
  File "C:\Users\sjalagam\AppData\Local\Programs\Python\Python313\Lib\site-packages\starlette\applications.py", line 112, in __call__
    await self.middleware_stack(scope, receive, send)
  File "C:\Users\sjalagam\AppData\Local\Programs\Python\Python313\Lib\site-packages\starlette\middleware\errors.py", line 187, in __call__
    raise exc
  File "C:\Users\sjalagam\AppData\Local\Programs\Python\Python313\Lib\site-packages\starlette\middleware\errors.py", line 165, in __call__
    await self.app(scope, receive, _send)
  File "C:\Users\sjalagam\AppData\Local\Programs\Python\Python313\Lib\site-packages\starlette\middleware\cors.py", line 85, in __call__
    await self.app(scope, receive, send)
  File "C:\Users\sjalagam\AppData\Local\Programs\Python\Python313\Lib\site-packages\starlette\middleware\exceptions.py", line 62, in __call__
    await wrap_app_handling_exceptions(self.app, conn)(scope, receive, send)
  File "C:\Users\sjalagam\AppData\Local\Programs\Python\Python313\Lib\site-packages\starlette\_exception_handler.py", line 53, in wrapped_app
    raise exc
  File "C:\Users\sjalagam\AppData\Local\Programs\Python\Python313\Lib\site-packages\starlette\_exception_handler.py", line 42, in wrapped_app
    await app(scope, receive, sender)
  File "C:\Users\sjalagam\AppData\Local\Programs\Python\Python313\Lib\site-packages\starlette\routing.py", line 714, in __call__
    await self.middleware_stack(scope, receive, send)
  File "C:\Users\sjalagam\AppData\Local\Programs\Python\Python313\Lib\site-packages\starlette\routing.py", line 734, in app
    await route.handle(scope, receive, send)
  File "C:\Users\sjalagam\AppData\Local\Programs\Python\Python313\Lib\site-packages\starlette\routing.py", line 288, in handle
    await self.app(scope, receive, send)
  File "C:\Users\sjalagam\AppData\Local\Programs\Python\Python313\Lib\site-packages\starlette\routing.py", line 76, in app
    await wrap_app_handling_exceptions(app, request)(scope, receive, send)
  File "C:\Users\sjalagam\AppData\Local\Programs\Python\Python313\Lib\site-packages\starlette\_exception_handler.py", line 53, in wrapped_app
    raise exc
  File "C:\Users\sjalagam\AppData\Local\Programs\Python\Python313\Lib\site-packages\starlette\_exception_handler.py", line 42, in wrapped_app
    await app(scope, receive, sender)
  File "C:\Users\sjalagam\AppData\Local\Programs\Python\Python313\Lib\site-packages\starlette\routing.py", line 73, in app
    response = await f(request)
               ^^^^^^^^^^^^^^^^
  File "C:\Users\sjalagam\AppData\Local\Programs\Python\Python313\Lib\site-packages\fastapi\routing.py", line 327, in app
    content = await serialize_response(
              ^^^^^^^^^^^^^^^^^^^^^^^^^
    ...<9 lines>...
    )
    ^
  File "C:\Users\sjalagam\AppData\Local\Programs\Python\Python313\Lib\site-packages\fastapi\routing.py", line 176, in serialize_response
    raise ResponseValidationError(
        errors=_normalize_errors(errors), body=response_content
    )
fastapi.exceptions.ResponseValidationError: 1 validation errors:
  {'type': 'list_type', 'loc': ('response',), 'msg': 'Input should be a valid list', 'input': {'projects': [{'id': 18, 'name': 'dev', 'train_id': None, 'connection': <projects.models.ConnectionProfile object at 0x000001B2338CFB10>, 'db_metadata': [<projects.models.TableSchema object at 0x000001B2338CFC50>]}, {'id': 22, 'name': 'test_project', 'train_id': 'test_train_001', 'connection': <projects.models.ConnectionProfile object at 0x000001B2338EA9E0>, 'db_metadata': []}]}}

